<robot
  name="dreko">
  <link
    name="chest">
    <inertial>
      <origin
        xyz="0.0004699 4.6862E-06 0.27495"
        rpy="0 0 0" />
        <mass
        value="0.458758046706296" />
      <inertia
        ixx="0.000523098946237096"
        ixy="8.78437497111212E-07"
        ixz="7.19687780172527E-06"
        iyy="0.000513875824890433"
        iyz="3.93144216279373E-06"
        izz="0.000807869475320241" />
    </inertial>
    <visual>
      <origin
        xyz="0 0 0"
        rpy="0 0 0" />
      <geometry>
        <mesh
          filename="package://swayat_description/meshes/chest.STL" />
      </geometry>
      <material
        name="">
        <color
          rgba="0.79216 0.81961 0.93333 1" />
      </material>
    </visual>
    <collision>
      <origin
        xyz="0 0 0"
        rpy="0 0 0" />
      <geometry>
        <mesh
          filename="package://swayat_description/meshes/chest.STL" />
      </geometry>
    </collision>
  </link>
  <link
    name="right hip yaw">
    <inertial>
      <origin
        xyz="-3.1521E-09 0.012643 -0.02044"
        rpy="0 0 0" />
       <mass
        value="0.0144774864798938" />
      <inertia
        ixx="1.14847231981558E-05"
        ixy="-5.25096456367368E-08"
        ixz="-1.2035048581476E-08"
        iyy="2.02418263757246E-06"
        iyz="-2.09973745724728E-08"
        izz="1.12136097911062E-05" />
    </inertial>
    <visual>
      <origin
        xyz="0 0 0"
        rpy="0 0 0" />
      <geometry>
        <mesh
          filename="package://swayat_description/meshes/right hip yaw.STL" />
      </geometry>
      <material
        name="">
        <color
          rgba="1 1 1 1" />
      </material>
    </visual>
    <collision>
      <origin
        xyz="0 0 0"
        rpy="0 0 0" />
      <geometry>
        <mesh
          filename="package://swayat_description/meshes/right hip yaw.STL" />
      </geometry>
    </collision>
  </link>
  <joint
    name="right hip yaw_joint"
    type="revolute">
    <origin
      xyz="0.01301 -0.038485 0.20945"
      rpy="3.1402 5.5511E-16 -1.5708"/>
    <parent
      link="chest" />
    <child
      link="right hip yaw" />
    <axis
      xyz="0 0 1" />
    <limit
      lower="-2.618"
      upper="2.618"
      effort="50"
      velocity="50" />
  </joint>
  <link
    name="right hip roll">
    <inertial>
      <origin
        xyz="0.012261 -0.00017357 0.012735"
        rpy="0 0 0" />
      <mass
        value="0.00432556668339446" />
      <inertia
        ixx="9.75405229303591E-07"
        ixy="-1.470579423867E-08"
        ixz="1.78859344232371E-07"
        iyy="1.04080815257891E-06"
        iyz="4.02570033654804E-08"
        izz="9.52575210528384E-07" />
    </inertial>
    <visual>
      <origin
        xyz="0 0 0"
        rpy="0 0 0" />
      <geometry>
        <mesh
          filename="package://swayat_description/meshes/right hip roll.STL" />
      </geometry>
      <material
        name="">
        <color
          rgba="1 1 1 1" />
      </material>
    </visual>
    <collision>
      <origin
        xyz="0 0 0"
        rpy="0 0 0" />
      <geometry>
        <mesh
          filename="package://swayat_description/meshes/right hip roll.STL" />
      </geometry>
    </collision>
  </link>
  <joint
    name="right hip roll_joint"
    type="revolute">
    <origin
      xyz="0 0 0"
      rpy="1.5708 -1.5708 0" />
    <parent
      link="right hip yaw" />
    <child
      link="right hip roll" />
    <axis
      xyz="0 0 1" />
    <limit
      lower="-2.618"
      upper="2.618"
      effort="50"
      velocity="50" />
  </joint>
  <link
    name="right hip pitch">
    <inertial>
      <origin
        xyz="0.0649437300196828 0.00045245863185972 0.000351698905364475"
        rpy="0 0 0" />
      <mass
        value="0.0111620558640124" />
      <inertia
        ixx="3.60701504991528E-06"
        ixy="-4.6921390113152E-18"
        ixz="-2.58410254235777E-07"
        iyy="7.73644086593341E-06"
        iyz="2.9201460856592E-19"
        izz="5.24114704838787E-06" />
    </inertial>
    <visual>
      <origin
        xyz="0 0 0"
        rpy="0 0 0" />
      <geometry>
        <mesh
          filename="package://swayat_description/meshes/right hip pitch.STL" />
      </geometry>
      <material
        name="">
        <color
          rgba="1 1 1 1" />
      </material>
    </visual>
    <collision>
      <origin
        xyz="0 0 0"
        rpy="0 0 0" />
      <geometry>
        <mesh
          filename="package://swayat_description/meshes/right hip pitch.STL" />
      </geometry>
    </collision>
  </link>
  <joint
    name="right hip pitch"
    type="revolute">
    <origin
      xyz="0 0 0"
      rpy="1.5708 -5.5511E-17 0" />
    <parent
      link="right hip roll" />
    <child
      link="right hip pitch" />
    <axis
      xyz="0 0 1" />
    <limit
      lower="-2.61799"
      upper="2.61799"
      effort="50"
      velocity="50" />
  </joint>
  <link
    name="right knee pitch">
    <inertial>
      <origin
        xyz="0.035367798616166 -0.00727201935500854 -0.000511604748993713"
        rpy="0 0 0" />
          <mass
        value="0.0246253166970604" />
      <inertia
        ixx="1.08052112483814E-05"
        ixy="3.56389856427867E-06"
        ixz="-1.54931774531241E-09"
        iyy="3.04273445861018E-05"
        iyz="2.65111632061903E-10"
        izz="2.60976831342102E-05" />
    </inertial>
    <visual>
      <origin
        xyz="0 0 0"
        rpy="0 0 0" />
      <geometry>
        <mesh
          filename="package://swayat_description/meshes/right knee pitch.STL" />
      </geometry>
      <material
        name="">
        <color
          rgba="1 1 1 1" />
      </material>
    </visual>
    <collision>
      <origin
        xyz="0 0 0"
        rpy="0 0 0" />
      <geometry>
        <mesh
          filename="package://swayat_description/meshes/right knee pitch.STL" />
      </geometry>
    </collision>
  </link>
  <joint
    name="right knee pitch"
    type="revolute">
    <origin
      xyz="0.089292 0.0017587 0.0011116"
      rpy="2.2204E-16 1.1935E-15 -0.0013546" />
    <parent
      link="right hip pitch" />
    <child
      link="right knee pitch" />
    <axis
      xyz="0 0 1" />
    <limit
      lower="-2.61799"
      upper="2.61799"
      effort="50"
      velocity="50" />
  </joint>
  <link
    name="right ankle pitch">
    <inertial>
      <origin
        xyz="-0.0121152197355968 0.0108424611095495 -2.58467488024605E-05"
        rpy="0 0 0" />
      <mass
        value="0.00432556668339446" />
      <inertia
        ixx="9.81566269037882E-07"
        ixy="-1.80265751262142E-07"
        ixz="-1.18889748283659E-08"
        iyy="9.53871558078931E-07"
        iyz="-5.08496466764315E-08"
        izz="1.04522930181063E-06" />
    </inertial>
    <visual>
      <origin
        xyz="0 0 0"
        rpy="0 0 0" />
      <geometry>
        <mesh
          filename="package://swayat_description/meshes/right ankle pitch.STL" />
      </geometry>
      <material
        name="">
        <color
          rgba="1 1 1 1" />
      </material>
    </visual>
    <collision>
      <origin
        xyz="0 0 0"
        rpy="0 0 0" />
      <geometry>
        <mesh
          filename="package://swayat_description/meshes/right ankle pitch.STL" />
      </geometry>
    </collision>
  </link>
  <joint
    name="right ankle pitch"
    type="revolute">
    <origin
      xyz="0.091994 0.00074366 -0.00091925"
      rpy="1.2212E-15 -5.5511E-16 1.1102E-16" />
    <parent
      link="right knee pitch" />
    <child
      link="right ankle pitch" />
    <axis
      xyz="0 0 1" />
    <limit
      lower="-2.61799"
      upper="2.61799"
      effort="50"
      velocity="50" />
  </joint>
  <link
    name="right ankle roll">
    <inertial>
      <origin
        xyz="0.0236287423644288 -0.0841214316395735 0.010144224343467"
        rpy="0 0 0" />
     <mass
        value="0.0286630906544186" />
      <inertia
        ixx="3.25315459968581E-05"
        ixy="4.27776503434535E-07"
        ixz="1.23434570556537E-08"
        iyy="2.61009320486312E-05"
        iyz="2.49642436979291E-09"
        izz="9.23186424475584E-06" />
    </inertial>
    <visual>
      <origin
        xyz="0 0 0"
        rpy="0 0 0" />
      <geometry>
        <mesh
          filename="package://swayat_description/meshes/right ankle roll.STL" />
      </geometry>
      <material
        name="">
        <color
          rgba="0.752941176470588 0.752941176470588 0.752941176470588 1" />
      </material>
    </visual>
    <collision>
      <origin
        xyz="0 0 0"
        rpy="0 0 0" />
      <geometry>
        <mesh
          filename="package://swayat_description/meshes/right ankle roll.STL" />
      </geometry>
    </collision>
  </link>
  <joint
    name="right ankle roll"
    type="revolute">
    <origin
      xyz="0 0 0"
      rpy="-1.5708 -8.3267E-17 1.1102E-16" />
    <parent
      link="right ankle pitch" />
    <child
      link="right ankle roll" />
    <axis
      xyz="0 0 1" />
    <limit
      lower="-2.61799"
      upper="2.61799"
      effort="50"
      velocity="50" />
  </joint>
  <link
    name="left hip yaw">
    <inertial>
      <origin
        xyz="0.00095 0.012643 -0.02044"
        rpy="0 0 0" />
       <mass
        value="0.0144774864798938" />
      <inertia
        ixx="1.14847231981559E-05"
        ixy="1.81187142312477E-08"
        ixz="-3.10745226456518E-10"
        iyy="2.02327283822937E-06"
        iyz="-2.09973745725232E-08"
        izz="1.12126999917632E-05" />
    </inertial>
    <visual>
      <origin
        xyz="0 0 0"
        rpy="0 0 0" />
      <geometry>
        <mesh
          filename="package://swayat_description/meshes/left hip yaw.STL" />
      </geometry>
      <material
        name="">
        <color
          rgba="1 1 1 1" />
      </material>
    </visual>
    <collision>
      <origin
        xyz="0 0 0"
        rpy="0 0 0" />
      <geometry>
        <mesh
          filename="package://swayat_description/meshes/left hip yaw.STL" />
      </geometry>
    </collision>
  </link>
  <joint
    name="left hip yaw"
    type="revolute">
    <origin
      xyz="0.01301 0.039445 0.20945"
      rpy="3.1402 -3.6082E-16 -1.5708" />
    <parent
      link="chest" />
    <child
      link="left hip yaw" />
    <axis
      xyz="0 0 1" />
    <limit
      lower="-2.61799"
      upper="2.61799"
      effort="50"
      velocity="50" />
  </joint>
  <link
    name="left hip roll">
    <inertial>
      <origin
        xyz="0.0122610856433649 0.00111650376164447 0.0127346861077619"
        rpy="0 0 0" />
      <mass
        value="0.00432556668339447" />
      <inertia
        ixx="9.80677879310102E-07"
        ixy="1.66610558994878E-08"
        ixz="1.78859344232139E-07"
        iyy="1.0408081525789E-06"
        iyz="-4.58346391819426E-08"
        izz="9.57847860534813E-07" />
    </inertial>
    <visual>
      <origin
        xyz="0 0 0"
        rpy="0 0 0" />
      <geometry>
        <mesh
          filename="package://swayat_description/meshes/left hip roll.STL" />
      </geometry>
      <material
        name="">
        <color
          rgba="1 1 1 1" />
      </material>
    </visual>
    <collision>
      <origin
        xyz="0 0 0"
        rpy="0 0 0" />
      <geometry>
        <mesh
          filename="package://swayat_description/meshes/left hip roll.STL" />
      </geometry>
    </collision>
  </link>
  <joint
    name="left hip roll"
    type="revolute">
    <origin
      xyz="0 0 0"
      rpy="-1.5708 -1.5708 0" />
    <parent
      link="left hip yaw" />
    <child
      link="left hip roll" />
    <axis
      xyz="0 0 -1" />
    <limit
      lower="-2.61799"
      upper="2.61799"
      effort="50"
      velocity="50" />
  </joint>
  <link
    name="left hip pitch">
    <inertial>
      <origin
        xyz="0.0649438119314808 3.3584246494911E-15 0.00130169575324036"
        rpy="0 0 0" />
   <mass
        value="0.0111620558640124" />
      <inertia
        ixx="3.60701612780146E-06"
        ixy="2.10975240495953E-09"
        ixz="-2.58410220507749E-07"
        iyy="7.73643978804455E-06"
        iyz="-1.32023615576981E-10"
        izz="5.24114704838779E-06" />
    </inertial>
    <visual>
      <origin
        xyz="0 0 0"
        rpy="0 0 0" />
      <geometry>
        <mesh
          filename="package://swayat_description/meshes/left hip pitch.STL" />
      </geometry>
      <material
        name="">
        <color
          rgba="1 1 1 1" />
      </material>
    </visual>
    <collision>
      <origin
        xyz="0 0 0"
        rpy="0 0 0" />
      <geometry>
        <mesh
          filename="package://swayat_description/meshes/left hip pitch.STL" />
      </geometry>
    </collision>
  </link>
  <joint
    name="left hip pitch"
    type="revolute">
    <origin
      xyz="0 0 0"
      rpy="-1.5708 0 0" />
    <parent
      link="left hip roll" />
    <child
      link="left hip pitch" />
    <axis
      xyz="0 0 1" />
    <limit
      lower="-2.61799"
      upper="2.61799"
      effort="50"
      velocity="50" />
  </joint>
  <link
    name="left knee pitch">
    <inertial>
      <origin
        xyz="0.0400959168464701 -0.0176924663710333 -0.00430003173604789"
        rpy="0 0 0" />
    <mass
        value="0.0246253166970604" />
      <inertia
        ixx="1.0800704143639E-05"
        ixy="-3.55702249204545E-06"
        ixz="1.35807698535455E-09"
        iyy="3.04301400351007E-05"
        iyz="-4.16230973293111E-09"
        izz="2.60959714784666E-05" />
    </inertial>
    <visual>
      <origin
        xyz="0 0 0"
        rpy="0 0 0" />
      <geometry>
        <mesh
          filename="package://swayat_description/meshes/left knee pitch.STL" />
      </geometry>
      <material
        name="">
        <color
          rgba="1 1 1 1" />
      </material>
    </visual>
    <collision>
      <origin
        xyz="0 0 0"
        rpy="0 0 0" />
      <geometry>
        <mesh
          filename="package://swayat_description/meshes/left knee pitch.STL" />
      </geometry>
    </collision>
  </link>
  <joint
    name="left knee pitch"
    type="revolute">
    <origin
      xyz="0.084562 0.023816 0.00585"
      rpy="9.4369E-16 7.7716E-16 -6.1062E-16" />
    <parent
      link="left hip pitch" />
    <child
      link="left knee pitch" />
    <axis
      xyz="0 0 -1" />
    <limit
      lower="-2.61799"
      upper="2.61799"
      effort="50"
      velocity="50" />
  </joint>
  <link
    name="left ankle pitch">
    <inertial>
      <origin
        xyz="-0.0122610741736412 -0.0127673651896271 0.000171690413861517"
        rpy="0 0 0" />
   <mass
        value="0.00432556668339446" />
      <inertia
        ixx="9.75405229296585E-07"
        ixy="1.79359845227328E-07"
        ixz="-1.90384430041769E-08"
        iyy="9.52738879873719E-07"
        iyz="4.0257003365211E-08"
        izz="1.04097182191722E-06" />
    </inertial>
    <visual>
      <origin
        xyz="0 0 0"
        rpy="0 0 0" />
      <geometry>
        <mesh
          filename="package://swayat_description/meshes/left ankle pitch.STL" />
      </geometry>
      <material
        name="">
        <color
          rgba="1 1 1 1" />
      </material>
    </visual>
    <collision>
      <origin
        xyz="0 0 0"
        rpy="0 0 0" />
      <geometry>
        <mesh
          filename="package://swayat_description/meshes/left ankle pitch.STL" />
      </geometry>
    </collision>
  </link>
  <joint
    name="left ankle pitch"
    type="revolute">
    <origin
      xyz="0.096868 -0.023783 -0.0048982"
      rpy="-3.3307E-16 -2.7756E-17 1.1102E-16" />
    <parent
      link="left knee pitch" />
    <child
      link="left ankle pitch" />
    <axis
      xyz="0 0 -1" />
    <limit
      lower="-2.61799"
      upper="2.61799"
      effort="50"
      velocity="50" />
  </joint>
  <link
    name="left ankle roll">
    <inertial>
      <origin
        xyz="0.0235159006243336 0.0843119082770712 0.0129762073799278"
        rpy="0 0 0" />
    <mass
        value="0.0286630906544186" />
      <inertia
        ixx="3.24224777208369E-05"
        ixy="-3.32353013416854E-07"
        ixz="-2.1100172385649E-07"
        iyy="2.61023036367036E-05"
        iyz="1.69060382964847E-07"
        izz="9.12489187788679E-06" />
    </inertial>
    <visual>
      <origin
        xyz="0 0 0"
        rpy="0 0 0" />
      <geometry>
        <mesh
          filename="package://swayat_description/meshes/left ankle roll.STL" />
      </geometry>
      <material
        name="">
        <color
          rgba="0.752941176470588 0.752941176470588 0.752941176470588 1" />
      </material>
    </visual>
    <collision>
      <origin
        xyz="0 0 0"
        rpy="0 0 0" />
      <geometry>
        <mesh
          filename="package://swayat_description/meshes/left ankle roll.STL" />
      </geometry>
    </collision>
  </link>
  <joint
    name="left ankle roll"
    type="revolute">
    <origin
      xyz="0 0 0"
      rpy="1.5708 -2.7756E-17 1.1102E-16" />
    <parent
      link="left ankle pitch" />
    <child
      link="left ankle roll" />
    <axis
      xyz="0 0 -1" />
    <limit
      lower="-2.61799"
      upper="2.61799"
      effort="50"
      velocity="50" />
  </joint>
<gazebo reference="right hip yaw">
    <selfCollide>true</selfCollide>
</gazebo>

<gazebo reference="right hip roll">
    <selfCollide>true</selfCollide>
</gazebo>

<gazebo reference="right hip pitch">
    <selfCollide>true</selfCollide>
</gazebo>
<gazebo reference="right knee pitch">
    <selfCollide>true</selfCollide>
</gazebo>
<gazebo reference="right ankle pitch">
    <selfCollide>true</selfCollide>
</gazebo>
<gazebo reference="right ankle roll">
    <selfCollide>true</selfCollide>
</gazebo>
<gazebo reference="left hip yaw">
    <selfCollide>true</selfCollide>
</gazebo>

<gazebo reference="left hip roll">
    <selfCollide>true</selfCollide>
</gazebo>

<gazebo reference="left hip pitch">
    <selfCollide>true</selfCollide>
</gazebo>
<gazebo reference="left knee pitch">
    <selfCollide>true</selfCollide>
</gazebo>
<gazebo reference="left ankle pitch">
    <selfCollide>true</selfCollide>
</gazebo>
<gazebo reference="left ankle roll">
    <selfCollide>true</selfCollide>
</gazebo>
</robot>
